Workbook
Name AccountList: ChartOfAccounts!$A$2:$A$100

Sheet Home
A1: PROFESSIONAL ACCOUNTING SYSTEM
A3: Journal → General Ledger → Trial Balance → Financial Statements | Professional workbook edition
A5: TOTAL REVENUE | C5: TOTAL EXPENSES | E5: NET PROFIT / (LOSS) | G5: BALANCE CHECK
A6: =FinancialStatements!B8 -> 9600 | C6: =FinancialStatements!B15 -> 7500 | E6: =FinancialStatements!B16 -> 2100 | G6: =ABS(FinancialStatements!B34) -> 0
A9: HOW TO USE
A10: 1 | B10: ChartOfAccounts | C10: Maintain your account master list.
A11: 2 | B11: NewTransaction | C11: Enter one balanced transaction per row.
A12: 3 | B12: Journal | C12: Review automated double-entry postings.
A13: 4 | B13: Ledger / TAccounts | C13: Review account-level balances.
A14: 5 | B14: TrialBalance | C14: Confirm total debits equal total credits.
A15: 6 | B15: FinancialStatements | C15: Review P&L and Balance Sheet.
A16: 7 | B16: Controls | C16: Resolve any CHECK status before reporting.
A19: QUICK NAVIGATION
A20: NewTransaction | C20: Journal | E20: Ledger | G20: TrialBalance
A21: FinancialStatements | C21: Controls | E21: Ratios | G21: KPIs
A23: CONTROL NOTE: Green/OK = ready for review. Red/CHECK = investigate before relying on reports. Hidden legacy sheets are retained to preserve the original workbook contents.
A26: ECONOMIC / MANAGEMENT TOOLS
A27: Economic_Dashboard | B27: Management-level KPI and decision view
A28: Economic_Model | B28: 12-month forecast driven by economic assumptions
A29: Scenario_Analysis | B29: Downside/base/upside and sensitivity analysis
A30: BreakEven | B30: Contribution margin and break-even analysis
A31: Working_Capital | B31: Liquidity and working-capital economics
A32: Productivity | B32: Output, labour intensity and unit economics
A33: Budget_Variance | B33: Actual vs budget variance analysis
A34: Macro_Inputs | B34: Macroeconomic assumptions with source/date fields

Sheet Economic_Dashboard
A1: ECONOMIC DASHBOARD
A3: METRIC | B3: VALUE | C3: LENS | E3: MANAGEMENT QUESTIONS
A4: Revenue | B4: =FinancialStatements!B8 -> 9600 | C4: Accounting | E4: • Is growth coming from volume, price, or both?
A5: Net Profit | B5: =FinancialStatements!B16 -> 2100 | C5: Accounting | E5: • Are wages rising faster than revenue?
A6: Net Margin | B6: =IFERROR(FinancialStatements!B16/FinancialStatements!B8,0) -> 0.21875 | C6: Accounting | E6: • How much working capital is required for growth?
A7: Current Ratio | B7: =Ratios!C2 -> 1.0060484 | C7: Liquidity | E7: • Where is the break-even point?
A8: Break-even Revenue | B8: =BreakEven!B12 -> 10000 | C8: Economic | E8: • How sensitive is profit to COGS and demand?
A9: Margin of Safety % | B9: =BreakEven!B15 -> -0.041666667 | C9: Economic | E9: • Does new capital create enough incremental return?
A10: Year 1 Forecast Revenue | B10: =Economic_Model!L5 -> 161095.01 | C10: Forecast
A11: Year 1 Forecast Operating Profit | B11: =Economic_Model!L7 -> 3619.9749 | C11: Forecast
A12: Year 1 Forecast Net Profit | B12: =Economic_Model!L8 -> 2797.9475 | C12: Forecast
A13: Forecast Net Margin | B13: =Economic_Model!L11 -> 0.017368306 | C13: Forecast
A17: Decision framework
A18: Use accounting for measurement, economics for explanation, and scenario analysis for uncertainty. Interpret KPIs together rather than in isolation.

Sheet Economic_Model
A1: ECONOMIC & MANAGEMENT MODEL
A2: Accounting measures what happened; this model adds the economic drivers behind revenue, costs, productivity and uncertainty.
A4: Base monthly revenue | B4: =FinancialStatements!B8 -> 9600 | C4: Replace with a normalised month if the accounting period is partial. | K4: FORECAST KPIs
A5: COGS % of revenue | B5: 0.25 | C5: Direct/variable cost share. | K5: Year 1 Revenue | L5: =SUM(B18:B29) -> 161095.01
A6: Fixed monthly operating costs | B6: =FinancialStatements!B15 -> 7500 | C6: Use a normalised monthly cost base. | K6: Year 1 Gross Profit | L6: =SUM(D18:D29) -> 120821.26
A7: Monthly volume growth | B7: 0.03 | C7: Expected activity/units growth. | K7: Year 1 Operating Profit | L7: =SUM(F18:F29) -> 3619.9749
A8: Price growth | B8: 0.02 | C8: Expected selling-price growth. | K8: Year 1 Net Profit | L8: =SUM(H18:H29) -> 2797.9475
A9: Wage inflation | B9: 0.04 | C9: Expected wage-cost growth. | K9: Gross Margin | L9: =IFERROR(L6/L5,0) -> 0.75
A10: General cost inflation | B10: 0.025 | C10: Expected non-wage cost growth. | K10: Operating Margin | L10: =IFERROR(L7/L5,0) -> 0.022471055
A11: Working-capital % of revenue | B11: 0.1 | C11: Approximate working-capital requirement. | K11: Net Margin | L11: =IFERROR(L8/L5,0) -> 0.017368306
A12: Tax rate | B12: 0.2 | C12: Planning assumption; replace with the relevant effective rate. | K12: Month 12 Revenue Growth | L12: =IFERROR(B29/B18-1,0) -> 0.72112083
A13: Discount rate | B13: 0.08 | C13: Planning rate for investment/NPV analysis.
A16: 12-MONTH FORECAST
A17: Month | B17: Revenue | C17: COGS | D17: Gross Profit | E17: Operating Costs | F17: Operating Profit | G17: Tax | H17: Net Profit | I17: Working Capital
A18: Month 1 | B18: =$B$4*(1+$B$7)^1*(1+$B$8)^1 -> 10085.76 | C18: =B18*$B$5 -> 2521.44 | D18: =B18-C18 -> 7564.32 | E18: =$B$6*(1+$B$9)^1 -> 7800 | F18: =D18-E18 -> -235.68 | G18: =MAX(0,F18*$B$12) -> 0 | H18: =F18-G18 -> -235.68 | I18: =B18*$B$11 -> 1008.576
A19: Month 2 | B19: =$B$4*(1+$B$7)^2*(1+$B$8)^2 -> 10596.099 | C19: =B19*$B$5 -> 2649.0249 | D19: =B19-C19 -> 7947.0746 | E19: =$B$6*(1+$B$9)^2 -> 8112 | F19: =D19-E19 -> -164.92541 | G19: =MAX(0,F19*$B$12) -> 0 | H19: =F19-G19 -> -164.92541 | I19: =B19*$B$11 -> 1059.6099
A20: Month 3 | B20: =$B$4*(1+$B$7)^3*(1+$B$8)^3 -> 11132.262 | C20: =B20*$B$5 -> 2783.0655 | D20: =B20-C20 -> 8349.1966 | E20: =$B$6*(1+$B$9)^3 -> 8436.48 | F20: =D20-E20 -> -87.283434 | G20: =MAX(0,F20*$B$12) -> 0 | H20: =F20-G20 -> -87.283434 | I20: =B20*$B$11 -> 1113.2262
A21: Month 4 | B21: =$B$4*(1+$B$7)^4*(1+$B$8)^4 -> 11695.555 | C21: =B21*$B$5 -> 2923.8886 | D21: =B21-C21 -> 8771.6659 | E21: =$B$6*(1+$B$9)^4 -> 8773.9392 | F21: =D21-E21 -> -2.2732874 | G21: =MAX(0,F21*$B$12) -> 0 | H21: =F21-G21 -> -2.2732874 | I21: =B21*$B$11 -> 1169.5555
A22: Month 5 | B22: =$B$4*(1+$B$7)^5*(1+$B$8)^5 -> 12287.35 | C22: =B22*$B$5 -> 3071.8374 | D22: =B22-C22 -> 9215.5122 | E22: =$B$6*(1+$B$9)^5 -> 9124.8968 | F22: =D22-E22 -> 90.61544 | G22: =MAX(0,F22*$B$12) -> 18.123088 | H22: =F22-G22 -> 72.492352 | I22: =B22*$B$11 -> 1228.735
A23: Month 6 | B23: =$B$4*(1+$B$7)^6*(1+$B$8)^6 -> 12909.09 | C23: =B23*$B$5 -> 3227.2724 | D23: =B23-C23 -> 9681.8171 | E23: =$B$6*(1+$B$9)^6 -> 9489.8926 | F23: =D23-E23 -> 191.92449 | G23: =MAX(0,F23*$B$12) -> 38.384897 | H23: =F23-G23 -> 153.53959 | I23: =B23*$B$11 -> 1290.909
A24: Month 7 | B24: =$B$4*(1+$B$7)^7*(1+$B$8)^7 -> 13562.289 | C24: =B24*$B$5 -> 3390.5724 | D24: =B24-C24 -> 10171.717 | E24: =$B$6*(1+$B$9)^7 -> 9869.4883 | F24: =D24-E24 -> 302.22873 | G24: =MAX(0,F24*$B$12) -> 60.445746 | H24: =F24-G24 -> 241.78298 | I24: =B24*$B$11 -> 1356.2289
A25: Month 8 | B25: =$B$4*(1+$B$7)^8*(1+$B$8)^8 -> 14248.541 | C25: =B25*$B$5 -> 3562.1353 | D25: =B25-C25 -> 10686.406 | E25: =$B$6*(1+$B$9)^8 -> 10264.268 | F25: =D25-E25 -> 422.13808 | G25: =MAX(0,F25*$B$12) -> 84.427616 | H25: =F25-G25 -> 337.71046 | I25: =B25*$B$11 -> 1424.8541
A26: Month 9 | B26: =$B$4*(1+$B$7)^9*(1+$B$8)^9 -> 14969.517 | C26: =B26*$B$5 -> 3742.3794 | D26: =B26-C26 -> 11227.138 | E26: =$B$6*(1+$B$9)^9 -> 10674.839 | F26: =D26-E26 -> 552.2995 | G26: =MAX(0,F26*$B$12) -> 110.4599 | H26: =F26-G26 -> 441.8396 | I26: =B26*$B$11 -> 1496.9517
A27: Month 10 | B27: =$B$4*(1+$B$7)^10*(1+$B$8)^10 -> 15726.975 | C27: =B27*$B$5 -> 3931.7438 | D27: =B27-C27 -> 11795.231 | E27: =$B$6*(1+$B$9)^10 -> 11101.832 | F27: =D27-E27 -> 693.39915 | G27: =MAX(0,F27*$B$12) -> 138.67983 | H27: =F27-G27 -> 554.71932 | I27: =B27*$B$11 -> 1572.6975
A28: Month 11 | B28: =$B$4*(1+$B$7)^11*(1+$B$8)^11 -> 16522.76 | C28: =B28*$B$5 -> 4130.69 | D28: =B28-C28 -> 12392.07 | E28: =$B$6*(1+$B$9)^11 -> 11545.905 | F28: =D28-E28 -> 846.16457 | G28: =MAX(0,F28*$B$12) -> 169.23291 | H28: =F28-G28 -> 676.93165 | I28: =B28*$B$11 -> 1652.276
A29: Month 12 | B29: =$B$4*(1+$B$7)^12*(1+$B$8)^12 -> 17358.812 | C29: =B29*$B$5 -> 4339.7029 | D29: =B29-C29 -> 13019.109 | E29: =$B$6*(1+$B$9)^12 -> 12007.742 | F29: =D29-E29 -> 1011.3671 | G29: =MAX(0,F29*$B$12) -> 202.27342 | H29: =F29-G29 -> 809.09367 | I29: =B29*$B$11 -> 1735.8812
A31: Economist's interpretation
A32: Separate volume growth, price growth, wage inflation and general cost inflation. This prevents a higher revenue figure from being mistaken automatically for higher real profitability.

Sheet Scenario_Analysis
A1: SCENARIO & SENSITIVITY ANALYSIS
A3: Scenario | B3: Revenue Growth | C3: COGS % | D3: Fixed Cost Growth | E3: Year 1 Revenue | F3: Year 1 Operating Profit | G3: Operating Margin
A4: Downside | B4: -0.05 | C4: 0.3 | D4: 0.05 | E4: =Economic_Model!$B$4*(1+B4)^12*(1+Economic_Model!$B$8)^12*12 -> 78947.395 | F4: =E4*(1-C4)-Economic_Model!$B$6*12*(1+D4)^12 -> -106363.89 | G4: =IFERROR(F4/E4,0) -> -1.3472755
A5: Base | B5: 0.03 | C5: 0.25 | D5: 0.025 | E5: =Economic_Model!$B$4*(1+B5)^12*(1+Economic_Model!$B$8)^12*12 -> 208305.74 | F5: =E5*(1-C5)-Economic_Model!$B$6*12*(1+D5)^12 -> 35189.311 | G5: =IFERROR(F5/E5,0) -> 0.16893107
A6: Upside | B6: 0.08 | C6: 0.22 | D6: 0.02 | E6: =Economic_Model!$B$4*(1+B6)^12*(1+Economic_Model!$B$8)^12*12 -> 367908.32 | F6: =E6*(1-C6)-Economic_Model!$B$6*12*(1+D6)^12 -> 172826.73 | G6: =IFERROR(F6/E6,0) -> 0.46975488
A9: Sensitivity: operating profit by revenue growth and COGS
A10: COGS \ Growth | B10: -0.05 | C10: -0.02 | D10: 0 | E10: 0.03 | F10: 0.05 | G10: 0.08
A11: COGS 20% | B11: =Economic_Model!$B$4*(1+B$10)^12*(1+Economic_Model!$B$8)^12*12*(1-$A11)-Economic_Model!$B$6*12*(1+Economic_Model!$B$9)^12 -> #VALUE! | C11: =Economic_Model!$B$4*(1+C$10)^12*(1+Economic_Model!$B$8)^12*12*(1-$A11)-Economic_Model!$B$6*12*(1+Economic_Model!$B$9)^12 -> #VALUE! | D11: =Economic_Model!$B$4*(1+D$10)^12*(1+Economic_Model!$B$8)^12*12*(1-$A11)-Economic_Model!$B$6*12*(1+Economic_Model!$B$9)^12 -> #VALUE! | E11: =Economic_Model!$B$4*(1+E$10)^12*(1+Economic_Model!$B$8)^12*12*(1-$A11)-Economic_Model!$B$6*12*(1+Economic_Model!$B$9)^12 -> #VALUE! | F11: =Economic_Model!$B$4*(1+F$10)^12*(1+Economic_Model!$B$8)^12*12*(1-$A11)-Economic_Model!$B$6*12*(1+Economic_Model!$B$9)^12 -> #VALUE! | G11: =Economic_Model!$B$4*(1+G$10)^12*(1+Economic_Model!$B$8)^12*12*(1-$A11)-Economic_Model!$B$6*12*(1+Economic_Model!$B$9)^12 -> #VALUE!
A12: COGS 25% | B12: =Economic_Model!$B$4*(1+B$10)^12*(1+Economic_Model!$B$8)^12*12*(1-$A12)-Economic_Model!$B$6*12*(1+Economic_Model!$B$9)^12 -> #VALUE! | C12: =Economic_Model!$B$4*(1+C$10)^12*(1+Economic_Model!$B$8)^12*12*(1-$A12)-Economic_Model!$B$6*12*(1+Economic_Model!$B$9)^12 -> #VALUE! | D12: =Economic_Model!$B$4*(1+D$10)^12*(1+Economic_Model!$B$8)^12*12*(1-$A12)-Economic_Model!$B$6*12*(1+Economic_Model!$B$9)^12 -> #VALUE! | E12: =Economic_Model!$B$4*(1+E$10)^12*(1+Economic_Model!$B$8)^12*12*(1-$A12)-Economic_Model!$B$6*12*(1+Economic_Model!$B$9)^12 -> #VALUE! | F12: =Economic_Model!$B$4*(1+F$10)^12*(1+Economic_Model!$B$8)^12*12*(1-$A12)-Economic_Model!$B$6*12*(1+Economic_Model!$B$9)^12 -> #VALUE! | G12: =Economic_Model!$B$4*(1+G$10)^12*(1+Economic_Model!$B$8)^12*12*(1-$A12)-Economic_Model!$B$6*12*(1+Economic_Model!$B$9)^12 -> #VALUE!
A13: COGS 30% | B13: =Economic_Model!$B$4*(1+B$10)^12*(1+Economic_Model!$B$8)^12*12*(1-$A13)-Economic_Model!$B$6*12*(1+Economic_Model!$B$9)^12 -> #VALUE! | C13: =Economic_Model!$B$4*(1+C$10)^12*(1+Economic_Model!$B$8)^12*12*(1-$A13)-Economic_Model!$B$6*12*(1+Economic_Model!$B$9)^12 -> #VALUE! | D13: =Economic_Model!$B$4*(1+D$10)^12*(1+Economic_Model!$B$8)^12*12*(1-$A13)-Economic_Model!$B$6*12*(1+Economic_Model!$B$9)^12 -> #VALUE! | E13: =Economic_Model!$B$4*(1+E$10)^12*(1+Economic_Model!$B$8)^12*12*(1-$A13)-Economic_Model!$B$6*12*(1+Economic_Model!$B$9)^12 -> #VALUE! | F13: =Economic_Model!$B$4*(1+F$10)^12*(1+Economic_Model!$B$8)^12*12*(1-$A13)-Economic_Model!$B$6*12*(1+Economic_Model!$B$9)^12 -> #VALUE! | G13: =Economic_Model!$B$4*(1+G$10)^12*(1+Economic_Model!$B$8)^12*12*(1-$A13)-Economic_Model!$B$6*12*(1+Economic_Model!$B$9)^12 -> #VALUE!
A14: COGS 35% | B14: =Economic_Model!$B$4*(1+B$10)^12*(1+Economic_Model!$B$8)^12*12*(1-$A14)-Economic_Model!$B$6*12*(1+Economic_Model!$B$9)^12 -> #VALUE! | C14: =Economic_Model!$B$4*(1+C$10)^12*(1+Economic_Model!$B$8)^12*12*(1-$A14)-Economic_Model!$B$6*12*(1+Economic_Model!$B$9)^12 -> #VALUE! | D14: =Economic_Model!$B$4*(1+D$10)^12*(1+Economic_Model!$B$8)^12*12*(1-$A14)-Economic_Model!$B$6*12*(1+Economic_Model!$B$9)^12 -> #VALUE! | E14: =Economic_Model!$B$4*(1+E$10)^12*(1+Economic_Model!$B$8)^12*12*(1-$A14)-Economic_Model!$B$6*12*(1+Economic_Model!$B$9)^12 -> #VALUE! | F14: =Economic_Model!$B$4*(1+F$10)^12*(1+Economic_Model!$B$8)^12*12*(1-$A14)-Economic_Model!$B$6*12*(1+Economic_Model!$B$9)^12 -> #VALUE! | G14: =Economic_Model!$B$4*(1+G$10)^12*(1+Economic_Model!$B$8)^12*12*(1-$A14)-Economic_Model!$B$6*12*(1+Economic_Model!$B$9)^12 -> #VALUE!
A16: Scenarios are planning ranges, not predictions. Update assumptions when evidence changes.

Sheet BreakEven
A1: BREAK-EVEN & CONTRIBUTION ANALYSIS
A3: Input | B3: Value | C3: Meaning
A4: Monthly revenue | B4: =Economic_Model!B4 -> 9600 | C4: Revenue base
A5: Variable cost % | B5: =Economic_Model!B5 -> 0.25 | C5: Direct/variable cost share
A6: Fixed operating costs | B6: =Economic_Model!B6 -> 7500 | C6: Costs that do not vary directly with volume
A7: Average selling price / unit | B7: 100 | C7: Editable planning assumption
A8: Variable cost / unit | B8: =B7*B5 -> 25 | C8: Selling price × variable cost %
A10: Contribution margin % | B10: =1-B5 -> 0.75
A11: Contribution / unit | B11: =B7-B8 -> 75
A12: Break-even revenue | B12: =IFERROR(B6/B10,0) -> 10000
A13: Break-even units | B13: =IFERROR(B6/B11,0) -> 100
A14: Margin of safety | B14: =B4-B12 -> -400
A15: Margin of safety % | B15: =IFERROR(B14/B4,0) -> -0.041666667
A17: Economic interpretation
A18: Contribution margin measures how much each additional unit of sales contributes toward fixed costs and profit. Break-even identifies the activity level at which operating profit is zero.

Sheet Working_Capital
A1: WORKING CAPITAL & LIQUIDITY ANALYSIS
A3: Metric | B3: Current | C3: Economic meaning
A4: Cash | B4: =FinancialStatements!B20 -> 40400 | C4: Immediate liquidity
A5: Accounts Receivable | B5: =FinancialStatements!B21 -> 1500 | C5: Capital tied up in customers
A6: Inventory | B6: =FinancialStatements!B22 -> 8000 | C6: Capital tied up in stock
A7: Accounts Payable | B7: =FinancialStatements!B29 -> 8000 | C7: Supplier financing
A8: Salaries Payable | B8: =FinancialStatements!B30 -> 1500 | C8: Accrued labour obligation
A9: Rent Payable | B9: =FinancialStatements!B31 -> 0 | C9: Accrued occupancy obligation
A10: Net Working Capital | B10: =SUM(B4:B6)-SUM(B7:B9) -> 40400 | C10: Operating current assets excluding cash less operating current liabilities
A11: Working Capital / Revenue | B11: =IFERROR(B10/Economic_Model!B4,0) -> 4.2083333 | C11: Working-capital intensity
A14: Management question | B14: How much cash is absorbed by receivables and inventory before sales become cash?

Sheet Productivity
A1: PRODUCTIVITY & UNIT ECONOMICS
A3: Metric | B3: Value | C3: Purpose
A4: Revenue / £1 operating cost | B4: =IFERROR(FinancialStatements!B8/FinancialStatements!B15,0) -> 1.28 | C4: Operating efficiency
A5: Net profit margin | B5: =IFERROR(FinancialStatements!B16/FinancialStatements!B8,0) -> 0.21875 | C5: Profitability
A6: Employees | B6: 1 | C6: Editable workforce assumption
A7: Revenue / employee | B7: =IFERROR(FinancialStatements!B8/B6,0) -> 9600 | C7: Output per worker
A8: Labour cost share | B8: =IFERROR(FinancialStatements!B11/FinancialStatements!B8,0) -> 0.48958333 | C8: Labour intensity
A10: Economist's lens | B10: Track output per unit of labour and capital, not just accounting profit. Productivity gains can improve margins even when prices remain unchanged.

Sheet Budget_Variance
A1: BUDGET VS ACTUAL VARIANCE
A3: Line Item | B3: Actual | C3: Budget | D3: Variance | E3: Variance % | F3: Interpretation
A4: Revenue | B4: =FinancialStatements!B8 -> 9600 | C4: =Economic_Model!B4 -> 9600 | D4: =B4-C4 -> 0 | E4: =IFERROR(D4/C4,0) -> 0 | F4: Positive = actual revenue above budget.
A5: Operating expenses | B5: =FinancialStatements!B15 -> 7500 | C5: =Economic_Model!B6 -> 7500 | D5: =B5-C5 -> 0 | E5: =IFERROR(D5/C5,0) -> 0 | F5: Positive = spending above budget.
A6: Net profit | B6: =FinancialStatements!B16 -> 2100 | C6: =Economic_Model!B4-Economic_Model!B6-Economic_Model!B4*Economic_Model!B5 -> -300 | D6: =B6-C6 -> 2400 | E6: =IFERROR(D6/ABS(C6),0) -> 8 | F6: Interpret with revenue and cost variances together.
A9: Better management reporting separates volume, price, mix and cost variances when operational data is available.

Sheet Macro_Inputs
A1: MACROECONOMIC INPUTS
A3: Indicator | B3: Assumption | C3: Use in model | D3: Source / date
A4: Inflation | B4: 0.025 | C4: General cost escalation | D4: Manual input
A5: Wage growth | B5: 0.04 | C5: Labour-cost planning | D5: Manual input
A6: Interest rate | B6: 0.04 | C6: Debt/financing sensitivity | D6: Manual input
A7: FX rate (EUR/GBP) | B7: 1.17 | C7: Cross-border planning | D7: Manual input
A8: Demand growth | B8: 0.03 | C8: Volume assumption | D8: Manual input
A11: Important | B11: These are planning assumptions, not live verified data. Add a dated official or market source before using them for formal decisions.

Sheet ChartOfAccounts
A1: Account | B1: Type | C1: Category
A2: Cash | B2: Asset | C2: Current Asset
A3: Accounts Receivable | B3: Asset | C3: Current Asset
A4: Inventory | B4: Asset | C4: Current Asset
A5: Prepaid Insurance | B5: Asset | C5: Current Asset
A6: Office Equipment | B6: Asset | C6: Non-Current Asset
A7: Accumulated Depreciation - Office Equipment | B7: Contra-Asset | C7: Non-Current Asset
A8: Accounts Payable | B8: Liability | C8: Current Liability
A9: Salaries Payable | B9: Liability | C9: Current Liability
A10: Loan Payable | B10: Liability | C10: Long-term Liability
A11: Owner's Capital | B11: Equity | C11: Owner's Equity
A12: Retained Earnings | B12: Equity | C12: Owner's Equity
... A31: Income Tax Expense | B31: Expense | C31: Tax

Sheet NewTransaction
A1: Date | B1: Description | C1: Debit Account | D1: Credit Account | E1: Amount | F1: Balanced?
A2: 46266 | B2: Owner investment | C2: Cash | D2: Owner's Capital | E2: 50000 | F2: =IF(COUNTA(A2:E2)=0,"",IF(AND(A2<>"",B2<>"",C2<>"",D2<>"",ISNUMBER(E2),E2>0,C2<>D2),"✓","CHECK")) -> ✓
A3: 46266 | B3: Equipment purchased for cash | C3: Office Equipment | D3: Cash | E3: 12000 | F3: =IF(COUNTA(A3:E3)=0,"",IF(AND(A3<>"",B3<>"",C3<>"",D3<>"",ISNUMBER(E3),E3>0,C3<>D3),"✓","CHECK")) -> ✓
A4: 46267 | B4: Inventory purchased on credit | C4: Inventory | D4: Accounts Payable | E4: 8000 | F4: =IF(COUNTA(A4:E4)=0,"",IF(AND(A4<>"",B4<>"",C4<>"",D4<>"",ISNUMBER(E4),E4>0,C4<>D4),"✓","CHECK")) -> ✓
A5: 46268 | B5: Rent paid | C5: Rent Expense | D5: Cash | E5: 2500 | F5: =IF(COUNTA(A5:E5)=0,"",IF(AND(A5<>"",B5<>"",C5<>"",D5<>"",ISNUMBER(E5),E5>0,C5<>D5),"✓","CHECK")) -> ✓
A6: 46269 | B6: Service revenue received | C6: Cash | D6: Service Revenue | E6: 5600 | F6: =IF(COUNTA(A6:E6)=0,"",IF(AND(A6<>"",B6<>"",C6<>"",D6<>"",ISNUMBER(E6),E6>0,C6<>D6),"✓","CHECK")) -> ✓
A7: 46270 | B7: Sales made on credit | C7: Accounts Receivable | D7: Sales Revenue | E7: 4000 | F7: =IF(COUNTA(A7:E7)=0,"",IF(AND(A7<>"",B7<>"",C7<>"",D7<>"",ISNUMBER(E7),E7>0,C7<>D7),"✓","CHECK")) -> ✓
A8: 46271 | B8: Salaries paid | C8: Salaries Expense | D8: Cash | E8: 3200 | F8: =IF(COUNTA(A8:E8)=0,"",IF(AND(A8<>"",B8<>"",C8<>"",D8<>"",ISNUMBER(E8),E8>0,C8<>D8),"✓","CHECK")) -> ✓
A9: 46272 | B9: Customer payment received | C9: Cash | D9: Accounts Receivable | E9: 2500 | F9: =IF(COUNTA(A9:E9)=0,"",IF(AND(A9<>"",B9<>"",C9<>"",D9<>"",ISNUMBER(E9),E9>0,C9<>D9),"✓","CHECK")) -> ✓
A10: 46273 | B10: Monthly depreciation | C10: Depreciation Expense | D10: Accumulated Depreciation - Office Equipment | E10: 300 | F10: =IF(COUNTA(A10:E10)=0,"",IF(AND(A10<>"",B10<>"",C10<>"",D10<>"",ISNUMBER(E10),E10>0,C10<>D10),"✓","CHECK")) -> ✓
A11: 46274 | B11: Salaries accrued | C11: Salaries Expense | D11: Salaries Payable | E11: 1500 | F11: =IF(COUNTA(A11:E11)=0,"",IF(AND(A11<>"",B11<>"",C11<>"",D11<>"",ISNUMBER(E11),E11>0,C11<>D11),"✓","CHECK")) -> ✓
F12: =IF(COUNTA(A12:E12)=0,"",IF(AND(A12<>"",B12<>"",C12<>"",D12<>"",ISNUMBER(E12),E12>0,C12<>D12),"✓","CHECK"))
F13: =IF(COUNTA(A13:E13)=0,"",IF(AND(A13<>"",B13<>"",C13<>"",D13<>"",ISNUMBER(E13),E13>0,C13<>D13),"✓","CHECK"))
F14: =IF(COUNTA(A14:E14)=0,"",IF(AND(A14<>"",B14<>"",C14<>"",D14<>"",ISNUMBER(E14),E14>0,C14<>D14),"✓","CHECK"))
F15: =IF(COUNTA(A15:E15)=0,"",IF(AND(A15<>"",B15<>"",C15<>"",D15<>"",ISNUMBER(E15),E15>0,C15<>D15),"✓","CHECK"))
F16: =IF(COUNTA(A16:E16)=0,"",IF(AND(A16<>"",B16<>"",C16<>"",D16<>"",ISNUMBER(E16),E16>0,C16<>D16),"✓","CHECK"))
F17: =IF(COUNTA(A17:E17)=0,"",IF(AND(A17<>"",B17<>"",C17<>"",D17<>"",ISNUMBER(E17),E17>0,C17<>D17),"✓","CHECK"))
F18: =IF(COUNTA(A18:E18)=0,"",IF(AND(A18<>"",B18<>"",C18<>"",D18<>"",ISNUMBER(E18),E18>0,C18<>D18),"✓","CHECK"))
F19: =IF(COUNTA(A19:E19)=0,"",IF(AND(A19<>"",B19<>"",C19<>"",D19<>"",ISNUMBER(E19),E19>0,C19<>D19),"✓","CHECK"))
F20: =IF(COUNTA(A20:E20)=0,"",IF(AND(A20<>"",B20<>"",C20<>"",D20<>"",ISNUMBER(E20),E20>0,C20<>D20),"✓","CHECK"))
F21: =IF(COUNTA(A21:E21)=0,"",IF(AND(A21<>"",B21<>"",C21<>"",D21<>"",ISNUMBER(E21),E21>0,C21<>D21),"✓","CHECK"))
F22: =IF(COUNTA(A22:E22)=0,"",IF(AND(A22<>"",B22<>"",C22<>"",D22<>"",ISNUMBER(E22),E22>0,C22<>D22),"✓","CHECK"))
F23: =IF(COUNTA(A23:E23)=0,"",IF(AND(A23<>"",B23<>"",C23<>"",D23<>"",ISNUMBER(E23),E23>0,C23<>D23),"✓","CHECK"))
... F99: =IF(COUNTA(A99:E99)=0,"",IF(AND(A99<>"",B99<>"",C99<>"",D99<>"",ISNUMBER(E99),E99>0,C99<>D99),"✓","CHECK"))

Sheet Journal
A1: Date | B1: Description | C1: Account | D1: Debit | E1: Credit
A2: =IF(NewTransaction!A2="","",NewTransaction!A2) -> 46266 | B2: =IF(NewTransaction!B2="","",NewTransaction!B2) -> Owner investment | C2: =IF(NewTransaction!C2="","",NewTransaction!C2) -> Cash | D2: =IF(NewTransaction!E2="","",NewTransaction!E2) -> 50000 | E2: =IF(NewTransaction!E2="","",0) -> 0
A3: =IF(NewTransaction!A2="","",NewTransaction!A2) -> 46266 | B3: =IF(NewTransaction!B2="","",NewTransaction!B2) -> Owner investment | C3: =IF(NewTransaction!D2="","",NewTransaction!D2) -> Owner's Capital | D3: =IF(NewTransaction!E2="","",0) -> 0 | E3: =IF(NewTransaction!E2="","",NewTransaction!E2) -> 50000
A4: =IF(NewTransaction!A3="","",NewTransaction!A3) -> 46266 | B4: =IF(NewTransaction!B3="","",NewTransaction!B3) -> Equipment purchased for cash | C4: =IF(NewTransaction!C3="","",NewTransaction!C3) -> Office Equipment | D4: =IF(NewTransaction!E3="","",NewTransaction!E3) -> 12000 | E4: =IF(NewTransaction!E3="","",0) -> 0
A5: =IF(NewTransaction!A3="","",NewTransaction!A3) -> 46266 | B5: =IF(NewTransaction!B3="","",NewTransaction!B3) -> Equipment purchased for cash | C5: =IF(NewTransaction!D3="","",NewTransaction!D3) -> Cash | D5: =IF(NewTransaction!E3="","",0) -> 0 | E5: =IF(NewTransaction!E3="","",NewTransaction!E3) -> 12000
A6: =IF(NewTransaction!A4="","",NewTransaction!A4) -> 46267 | B6: =IF(NewTransaction!B4="","",NewTransaction!B4) -> Inventory purchased on credit | C6: =IF(NewTransaction!C4="","",NewTransaction!C4) -> Inventory | D6: =IF(NewTransaction!E4="","",NewTransaction!E4) -> 8000 | E6: =IF(NewTransaction!E4="","",0) -> 0
A7: =IF(NewTransaction!A4="","",NewTransaction!A4) -> 46267 | B7: =IF(NewTransaction!B4="","",NewTransaction!B4) -> Inventory purchased on credit | C7: =IF(NewTransaction!D4="","",NewTransaction!D4) -> Accounts Payable | D7: =IF(NewTransaction!E4="","",0) -> 0 | E7: =IF(NewTransaction!E4="","",NewTransaction!E4) -> 8000
A8: =IF(NewTransaction!A5="","",NewTransaction!A5) -> 46268 | B8: =IF(NewTransaction!B5="","",NewTransaction!B5) -> Rent paid | C8: =IF(NewTransaction!C5="","",NewTransaction!C5) -> Rent Expense | D8: =IF(NewTransaction!E5="","",NewTransaction!E5) -> 2500 | E8: =IF(NewTransaction!E5="","",0) -> 0
A9: =IF(NewTransaction!A5="","",NewTransaction!A5) -> 46268 | B9: =IF(NewTransaction!B5="","",NewTransaction!B5) -> Rent paid | C9: =IF(NewTransaction!D5="","",NewTransaction!D5) -> Cash | D9: =IF(NewTransaction!E5="","",0) -> 0 | E9: =IF(NewTransaction!E5="","",NewTransaction!E5) -> 2500
A10: =IF(NewTransaction!A6="","",NewTransaction!A6) -> 46269 | B10: =IF(NewTransaction!B6="","",NewTransaction!B6) -> Service revenue received | C10: =IF(NewTransaction!C6="","",NewTransaction!C6) -> Cash | D10: =IF(NewTransaction!E6="","",NewTransaction!E6) -> 5600 | E10: =IF(NewTransaction!E6="","",0) -> 0
A11: =IF(NewTransaction!A6="","",NewTransaction!A6) -> 46269 | B11: =IF(NewTransaction!B6="","",NewTransaction!B6) -> Service revenue received | C11: =IF(NewTransaction!D6="","",NewTransaction!D6) -> Service Revenue | D11: =IF(NewTransaction!E6="","",0) -> 0 | E11: =IF(NewTransaction!E6="","",NewTransaction!E6) -> 5600
A12: =IF(NewTransaction!A7="","",NewTransaction!A7) -> 46270 | B12: =IF(NewTransaction!B7="","",NewTransaction!B7) -> Sales made on credit | C12: =IF(NewTransaction!C7="","",NewTransaction!C7) -> Accounts Receivable | D12: =IF(NewTransaction!E7="","",NewTransaction!E7) -> 4000 | E12: =IF(NewTransaction!E7="","",0) -> 0
A13: =IF(NewTransaction!A7="","",NewTransaction!A7) -> 46270 | B13: =IF(NewTransaction!B7="","",NewTransaction!B7) -> Sales made on credit | C13: =IF(NewTransaction!D7="","",NewTransaction!D7) -> Sales Revenue | D13: =IF(NewTransaction!E7="","",0) -> 0 | E13: =IF(NewTransaction!E7="","",NewTransaction!E7) -> 4000
A14: =IF(NewTransaction!A8="","",NewTransaction!A8) -> 46271 | B14: =IF(NewTransaction!B8="","",NewTransaction!B8) -> Salaries paid | C14: =IF(NewTransaction!C8="","",NewTransaction!C8) -> Salaries Expense | D14: =IF(NewTransaction!E8="","",NewTransaction!E8) -> 3200 | E14: =IF(NewTransaction!E8="","",0) -> 0
A15: =IF(NewTransaction!A8="","",NewTransaction!A8) -> 46271 | B15: =IF(NewTransaction!B8="","",NewTransaction!B8) -> Salaries paid | C15: =IF(NewTransaction!D8="","",NewTransaction!D8) -> Cash | D15: =IF(NewTransaction!E8="","",0) -> 0 | E15: =IF(NewTransaction!E8="","",NewTransaction!E8) -> 3200
A16: =IF(NewTransaction!A9="","",NewTransaction!A9) -> 46272 | B16: =IF(NewTransaction!B9="","",NewTransaction!B9) -> Customer payment received | C16: =IF(NewTransaction!C9="","",NewTransaction!C9) -> Cash | D16: =IF(NewTransaction!E9="","",NewTransaction!E9) -> 2500 | E16: =IF(NewTransaction!E9="","",0) -> 0
A17: =IF(NewTransaction!A9="","",NewTransaction!A9) -> 46272 | B17: =IF(NewTransaction!B9="","",NewTransaction!B9) -> Customer payment received | C17: =IF(NewTransaction!D9="","",NewTransaction!D9) -> Accounts Receivable | D17: =IF(NewTransaction!E9="","",0) -> 0 | E17: =IF(NewTransaction!E9="","",NewTransaction!E9) -> 2500
A18: =IF(NewTransaction!A10="","",NewTransaction!A10) -> 46273 | B18: =IF(NewTransaction!B10="","",NewTransaction!B10) -> Monthly depreciation | C18: =IF(NewTransaction!C10="","",NewTransaction!C10) -> Depreciation Expense | D18: =IF(NewTransaction!E10="","",NewTransaction!E10) -> 300 | E18: =IF(NewTransaction!E10="","",0) -> 0
A19: =IF(NewTransaction!A10="","",NewTransaction!A10) -> 46273 | B19: =IF(NewTransaction!B10="","",NewTransaction!B10) -> Monthly depreciation | C19: =IF(NewTransaction!D10="","",NewTransaction!D10) -> Accumulated Depreciation - Office Equipment | D19: =IF(NewTransaction!E10="","",0) -> 0 | E19: =IF(NewTransaction!E10="","",NewTransaction!E10) -> 300
A20: =IF(NewTransaction!A11="","",NewTransaction!A11) -> 46274 | B20: =IF(NewTransaction!B11="","",NewTransaction!B11) -> Salaries accrued | C20: =IF(NewTransaction!C11="","",NewTransaction!C11) -> Salaries Expense | D20: =IF(NewTransaction!E11="","",NewTransaction!E11) -> 1500 | E20: =IF(NewTransaction!E11="","",0) -> 0
A21: =IF(NewTransaction!A11="","",NewTransaction!A11) -> 46274 | B21: =IF(NewTransaction!B11="","",NewTransaction!B11) -> Salaries accrued | C21: =IF(NewTransaction!D11="","",NewTransaction!D11) -> Salaries Payable | D21: =IF(NewTransaction!E11="","",0) -> 0 | E21: =IF(NewTransaction!E11="","",NewTransaction!E11) -> 1500
A22: =IF(NewTransaction!A12="","",NewTransaction!A12) | B22: =IF(NewTransaction!B12="","",NewTransaction!B12) | C22: =IF(NewTransaction!C12="","",NewTransaction!C12) | D22: =IF(NewTransaction!E12="","",NewTransaction!E12) | E22: =IF(NewTransaction!E12="","",0)
A23: =IF(NewTransaction!A12="","",NewTransaction!A12) | B23: =IF(NewTransaction!B12="","",NewTransaction!B12) | C23: =IF(NewTransaction!D12="","",NewTransaction!D12) | D23: =IF(NewTransaction!E12="","",0) | E23: =IF(NewTransaction!E12="","",NewTransaction!E12)
A24: =IF(NewTransaction!A13="","",NewTransaction!A13) | B24: =IF(NewTransaction!B13="","",NewTransaction!B13) | C24: =IF(NewTransaction!C13="","",NewTransaction!C13) | D24: =IF(NewTransaction!E13="","",NewTransaction!E13) | E24: =IF(NewTransaction!E13="","",0)
A25: =IF(NewTransaction!A13="","",NewTransaction!A13) | B25: =IF(NewTransaction!B13="","",NewTransaction!B13) | C25: =IF(NewTransaction!D13="","",NewTransaction!D13) | D25: =IF(NewTransaction!E13="","",0) | E25: =IF(NewTransaction!E13="","",NewTransaction!E13)
A26: =IF(NewTransaction!A14="","",NewTransaction!A14) | B26: =IF(NewTransaction!B14="","",NewTransaction!B14) | C26: =IF(NewTransaction!C14="","",NewTransaction!C14) | D26: =IF(NewTransaction!E14="","",NewTransaction!E14) | E26: =IF(NewTransaction!E14="","",0)
A27: =IF(NewTransaction!A14="","",NewTransaction!A14) | B27: =IF(NewTransaction!B14="","",NewTransaction!B14) | C27: =IF(NewTransaction!D14="","",NewTransaction!D14) | D27: =IF(NewTransaction!E14="","",0) | E27: =IF(NewTransaction!E14="","",NewTransaction!E14)
A28: =IF(NewTransaction!A15="","",NewTransaction!A15) | B28: =IF(NewTransaction!B15="","",NewTransaction!B15) | C28: =IF(NewTransaction!C15="","",NewTransaction!C15) | D28: =IF(NewTransaction!E15="","",NewTransaction!E15) | E28: =IF(NewTransaction!E15="","",0)
A29: =IF(NewTransaction!A15="","",NewTransaction!A15) | B29: =IF(NewTransaction!B15="","",NewTransaction!B15) | C29: =IF(NewTransaction!D15="","",NewTransaction!D15) | D29: =IF(NewTransaction!E15="","",0) | E29: =IF(NewTransaction!E15="","",NewTransaction!E15)
A30: =IF(NewTransaction!A16="","",NewTransaction!A16) | B30: =IF(NewTransaction!B16="","",NewTransaction!B16) | C30: =IF(NewTransaction!C16="","",NewTransaction!C16) | D30: =IF(NewTransaction!E16="","",NewTransaction!E16) | E30: =IF(NewTransaction!E16="","",0)
A31: =IF(NewTransaction!A16="","",NewTransaction!A16) | B31: =IF(NewTransaction!B16="","",NewTransaction!B16) | C31: =IF(NewTransaction!D16="","",NewTransaction!D16) | D31: =IF(NewTransaction!E16="","",0) | E31: =IF(NewTransaction!E16="","",NewTransaction!E16)
A32: =IF(NewTransaction!A17="","",NewTransaction!A17) | B32: =IF(NewTransaction!B17="","",NewTransaction!B17) | C32: =IF(NewTransaction!C17="","",NewTransaction!C17) | D32: =IF(NewTransaction!E17="","",NewTransaction!E17) | E32: =IF(NewTransaction!E17="","",0)
A33: =IF(NewTransaction!A17="","",NewTransaction!A17) | B33: =IF(NewTransaction!B17="","",NewTransaction!B17) | C33: =IF(NewTransaction!D17="","",NewTransaction!D17) | D33: =IF(NewTransaction!E17="","",0) | E33: =IF(NewTransaction!E17="","",NewTransaction!E17)
A34: =IF(NewTransaction!A18="","",NewTransaction!A18) | B34: =IF(NewTransaction!B18="","",NewTransaction!B18) | C34: =IF(NewTransaction!C18="","",NewTransaction!C18) | D34: =IF(NewTransaction!E18="","",NewTransaction!E18) | E34: =IF(NewTransaction!E18="","",0)
A35: =IF(NewTransaction!A18="","",NewTransaction!A18) | B35: =IF(NewTransaction!B18="","",NewTransaction!B18) | C35: =IF(NewTransaction!D18="","",NewTransaction!D18) | D35: =IF(NewTransaction!E18="","",0) | E35: =IF(NewTransaction!E18="","",NewTransaction!E18)
A36: =IF(NewTransaction!A19="","",NewTransaction!A19) | B36: =IF(NewTransaction!B19="","",NewTransaction!B19) | C36: =IF(NewTransaction!C19="","",NewTransaction!C19) | D36: =IF(NewTransaction!E19="","",NewTransaction!E19) | E36: =IF(NewTransaction!E19="","",0)
A37: =IF(NewTransaction!A19="","",NewTransaction!A19) | B37: =IF(NewTransaction!B19="","",NewTransaction!B19) | C37: =IF(NewTransaction!D19="","",NewTransaction!D19) | D37: =IF(NewTransaction!E19="","",0) | E37: =IF(NewTransaction!E19="","",NewTransaction!E19)
A38: =IF(NewTransaction!A20="","",NewTransaction!A20) | B38: =IF(NewTransaction!B20="","",NewTransaction!B20) | C38: =IF(NewTransaction!C20="","",NewTransaction!C20) | D38: =IF(NewTransaction!E20="","",NewTransaction!E20) | E38: =IF(NewTransaction!E20="","",0)
A39: =IF(NewTransaction!A20="","",NewTransaction!A20) | B39: =IF(NewTransaction!B20="","",NewTransaction!B20) | C39: =IF(NewTransaction!D20="","",NewTransaction!D20) | D39: =IF(NewTransaction!E20="","",0) | E39: =IF(NewTransaction!E20="","",NewTransaction!E20)
A40: =IF(NewTransaction!A21="","",NewTransaction!A21) | B40: =IF(NewTransaction!B21="","",NewTransaction!B21) | C40: =IF(NewTransaction!C21="","",NewTransaction!C21) | D40: =IF(NewTransaction!E21="","",NewTransaction!E21) | E40: =IF(NewTransaction!E21="","",0)
...

Sheet Ledger
A1: Account | B1: Debit Total | C1: Credit Total | D1: Balance
A2: =IFERROR(INDEX(ChartOfAccounts!$A$2:$A$100,ROW()-1),"") -> Cash | B2: =IF(A2="","",SUMIF(Journal!$C:$C,A2,Journal!$D:$D)) -> 58100 | C2: =IF(A2="","",SUMIF(Journal!$C:$C,A2,Journal!$E:$E)) -> 17700 | D2: =IF(A2="","",B2-C2) -> 40400
A3: =IFERROR(INDEX(ChartOfAccounts!$A$2:$A$100,ROW()-1),"") -> Accounts Receivable | B3: =IF(A3="","",SUMIF(Journal!$C:$C,A3,Journal!$D:$D)) -> 4000 | C3: =IF(A3="","",SUMIF(Journal!$C:$C,A3,Journal!$E:$E)) -> 2500 | D3: =IF(A3="","",B3-C3) -> 1500
A4: =IFERROR(INDEX(ChartOfAccounts!$A$2:$A$100,ROW()-1),"") -> Inventory | B4: =IF(A4="","",SUMIF(Journal!$C:$C,A4,Journal!$D:$D)) -> 8000 | C4: =IF(A4="","",SUMIF(Journal!$C:$C,A4,Journal!$E:$E)) -> 0 | D4: =IF(A4="","",B4-C4) -> 8000
A5: =IFERROR(INDEX(ChartOfAccounts!$A$2:$A$100,ROW()-1),"") -> Prepaid Insurance | B5: =IF(A5="","",SUMIF(Journal!$C:$C,A5,Journal!$D:$D)) -> 0 | C5: =IF(A5="","",SUMIF(Journal!$C:$C,A5,Journal!$E:$E)) -> 0 | D5: =IF(A5="","",B5-C5) -> 0
A6: =IFERROR(INDEX(ChartOfAccounts!$A$2:$A$100,ROW()-1),"") -> Office Equipment | B6: =IF(A6="","",SUMIF(Journal!$C:$C,A6,Journal!$D:$D)) -> 12000 | C6: =IF(A6="","",SUMIF(Journal!$C:$C,A6,Journal!$E:$E)) -> 0 | D6: =IF(A6="","",B6-C6) -> 12000
A7: =IFERROR(INDEX(ChartOfAccounts!$A$2:$A$100,ROW()-1),"") -> Accumulated Depreciation - Office Equipment | B7: =IF(A7="","",SUMIF(Journal!$C:$C,A7,Journal!$D:$D)) -> 0 | C7: =IF(A7="","",SUMIF(Journal!$C:$C,A7,Journal!$E:$E)) -> 300 | D7: =IF(A7="","",B7-C7) -> -300
A8: =IFERROR(INDEX(ChartOfAccounts!$A$2:$A$100,ROW()-1),"") -> Accounts Payable | B8: =IF(A8="","",SUMIF(Journal!$C:$C,A8,Journal!$D:$D)) -> 0 | C8: =IF(A8="","",SUMIF(Journal!$C:$C,A8,Journal!$E:$E)) -> 8000 | D8: =IF(A8="","",B8-C8) -> -8000
A9: =IFERROR(INDEX(ChartOfAccounts!$A$2:$A$100,ROW()-1),"") -> Salaries Payable | B9: =IF(A9="","",SUMIF(Journal!$C:$C,A9,Journal!$D:$D)) -> 0 | C9: =IF(A9="","",SUMIF(Journal!$C:$C,A9,Journal!$E:$E)) -> 1500 | D9: =IF(A9="","",B9-C9) -> -1500
A10: =IFERROR(INDEX(ChartOfAccounts!$A$2:$A$100,ROW()-1),"") -> Loan Payable | B10: =IF(A10="","",SUMIF(Journal!$C:$C,A10,Journal!$D:$D)) -> 0 | C10: =IF(A10="","",SUMIF(Journal!$C:$C,A10,Journal!$E:$E)) -> 0 | D10: =IF(A10="","",B10-C10) -> 0
A11: =IFERROR(INDEX(ChartOfAccounts!$A$2:$A$100,ROW()-1),"") -> Owner's Capital | B11: =IF(A11="","",SUMIF(Journal!$C:$C,A11,Journal!$D:$D)) -> 0 | C11: =IF(A11="","",SUMIF(Journal!$C:$C,A11,Journal!$E:$E)) -> 50000 | D11: =IF(A11="","",B11-C11) -> -50000
A12: =IFERROR(INDEX(ChartOfAccounts!$A$2:$A$100,ROW()-1),"") -> Retained Earnings | B12: =IF(A12="","",SUMIF(Journal!$C:$C,A12,Journal!$D:$D)) -> 0 | C12: =IF(A12="","",SUMIF(Journal!$C:$C,A12,Journal!$E:$E)) -> 0 | D12: =IF(A12="","",B12-C12) -> 0
A13: =IFERROR(INDEX(ChartOfAccounts!$A$2:$A$100,ROW()-1),"") -> Drawings | B13: =IF(A13="","",SUMIF(Journal!$C:$C,A13,Journal!$D:$D)) -> 0 | C13: =IF(A13="","",SUMIF(Journal!$C:$C,A13,Journal!$E:$E)) -> 0 | D13: =IF(A13="","",B13-C13) -> 0
... A101: =IFERROR(INDEX(ChartOfAccounts!$A$2:$A$100,ROW()-1),"") | B101: =IF(A101="","",SUMIF(Journal!$C:$C,A101,Journal!$D:$D)) | C101: =IF(A101="","",SUMIF(Journal!$C:$C,A101,Journal!$E:$E)) | D101: =IF(A101="","",B101-C101)

Sheet TAccounts
A1: Account | B1: Debit | C1: Credit | D1: Net Balance
A2: =Ledger!A2 -> Cash | B2: =Ledger!B2 -> 58100 | C2: =Ledger!C2 -> 17700 | D2: =Ledger!D2 -> 40400
A3: =Ledger!A3 -> Accounts Receivable | B3: =Ledger!B3 -> 4000 | C3: =Ledger!C3 -> 2500 | D3: =Ledger!D3 -> 1500
A4: =Ledger!A4 -> Inventory | B4: =Ledger!B4 -> 8000 | C4: =Ledger!C4 -> 0 | D4: =Ledger!D4 -> 8000
A5: =Ledger!A5 -> Prepaid Insurance | B5: =Ledger!B5 -> 0 | C5: =Ledger!C5 -> 0 | D5: =Ledger!D5 -> 0
A6: =Ledger!A6 -> Office Equipment | B6: =Ledger!B6 -> 12000 | C6: =Ledger!C6 -> 0 | D6: =Ledger!D6 -> 12000
A7: =Ledger!A7 -> Accumulated Depreciation - Office Equipment | B7: =Ledger!B7 -> 0 | C7: =Ledger!C7 -> 300 | D7: =Ledger!D7 -> -300
A8: =Ledger!A8 -> Accounts Payable | B8: =Ledger!B8 -> 0 | C8: =Ledger!C8 -> 8000 | D8: =Ledger!D8 -> -8000
A9: =Ledger!A9 -> Salaries Payable | B9: =Ledger!B9 -> 0 | C9: =Ledger!C9 -> 1500 | D9: =Ledger!D9 -> -1500
A10: =Ledger!A10 -> Loan Payable | B10: =Ledger!B10 -> 0 | C10: =Ledger!C10 -> 0 | D10: =Ledger!D10 -> 0
A11: =Ledger!A11 -> Owner's Capital | B11: =Ledger!B11 -> 0 | C11: =Ledger!C11 -> 50000 | D11: =Ledger!D11 -> -50000
A12: =Ledger!A12 -> Retained Earnings | B12: =Ledger!B12 -> 0 | C12: =Ledger!C12 -> 0 | D12: =Ledger!D12 -> 0
A13: =Ledger!A13 -> Drawings | B13: =Ledger!B13 -> 0 | C13: =Ledger!C13 -> 0 | D13: =Ledger!D13 -> 0
... A101: =Ledger!A101 | B101: =Ledger!B101 | C101: =Ledger!C101 | D101: =Ledger!D101

Sheet TrialBalance
A1: Account | B1: Debit | C1: Credit
A2: =Ledger!A2 -> Cash | B2: =IF(Ledger!D2>0,Ledger!D2,"") -> 40400 | C2: =IF(Ledger!D2<0,-Ledger!D2,"")
A3: =Ledger!A3 -> Accounts Receivable | B3: =IF(Ledger!D3>0,Ledger!D3,"") -> 1500 | C3: =IF(Ledger!D3<0,-Ledger!D3,"")
A4: =Ledger!A4 -> Inventory | B4: =IF(Ledger!D4>0,Ledger!D4,"") -> 8000 | C4: =IF(Ledger!D4<0,-Ledger!D4,"")
A5: =Ledger!A5 -> Prepaid Insurance | B5: =IF(Ledger!D5>0,Ledger!D5,"") | C5: =IF(Ledger!D5<0,-Ledger!D5,"")
A6: =Ledger!A6 -> Office Equipment | B6: =IF(Ledger!D6>0,Ledger!D6,"") -> 12000 | C6: =IF(Ledger!D6<0,-Ledger!D6,"")
A7: =Ledger!A7 -> Accumulated Depreciation - Office Equipment | B7: =IF(Ledger!D7>0,Ledger!D7,"") | C7: =IF(Ledger!D7<0,-Ledger!D7,"") -> 300
A8: =Ledger!A8 -> Accounts Payable | B8: =IF(Ledger!D8>0,Ledger!D8,"") | C8: =IF(Ledger!D8<0,-Ledger!D8,"") -> 8000
A9: =Ledger!A9 -> Salaries Payable | B9: =IF(Ledger!D9>0,Ledger!D9,"") | C9: =IF(Ledger!D9<0,-Ledger!D9,"") -> 1500
A10: =Ledger!A10 -> Loan Payable | B10: =IF(Ledger!D10>0,Ledger!D10,"") | C10: =IF(Ledger!D10<0,-Ledger!D10,"")
A11: =Ledger!A11 -> Owner's Capital | B11: =IF(Ledger!D11>0,Ledger!D11,"") | C11: =IF(Ledger!D11<0,-Ledger!D11,"") -> 50000
A12: =Ledger!A12 -> Retained Earnings | B12: =IF(Ledger!D12>0,Ledger!D12,"") | C12: =IF(Ledger!D12<0,-Ledger!D12,"")
A13: =Ledger!A13 -> Drawings | B13: =IF(Ledger!D13>0,Ledger!D13,"") | C13: =IF(Ledger!D13<0,-Ledger!D13,"")
... A101: =Ledger!A101 | B101: =IF(Ledger!D101>0,Ledger!D101,"") | C101: =IF(Ledger!D101<0,-Ledger!D101,"")
A103: TOTAL | B103: =SUM(B2:B101) -> 69400 | C103: =SUM(C2:C101) -> 69400
A104: TOTAL | B104: =SUM(B2:B103) -> 138800 | C104: =SUM(C2:C103) -> 138800

Sheet FinancialStatements
A1: INCOME STATEMENT | B1: Amount
A2: Revenue
A3: Sales Revenue | B3: =SUMIF(TrialBalance!$A:$A,A3,TrialBalance!$C:$C) -> 4000
A4: Service Revenue | B4: =SUMIF(TrialBalance!$A:$A,A4,TrialBalance!$C:$C) -> 5600
A5: Interest Income | B5: =SUMIF(TrialBalance!$A:$A,A5,TrialBalance!$C:$C) -> 0
A6: Commission Income | B6: =SUMIF(TrialBalance!$A:$A,A6,TrialBalance!$C:$C) -> 0
A7: Rental Income | B7: =SUMIF(TrialBalance!$A:$A,A7,TrialBalance!$C:$C) -> 0
A8: Total Revenue | B8: =SUM(B3:B7) -> 9600
A9: Expenses
A10: Rent Expense | B10: =SUMIF(TrialBalance!$A:$A,A10,TrialBalance!$B:$B) -> 2500
A11: Salaries Expense | B11: =SUMIF(TrialBalance!$A:$A,A11,TrialBalance!$B:$B) -> 4700
A12: Utilities Expense | B12: =SUMIF(TrialBalance!$A:$A,A12,TrialBalance!$B:$B) -> 0
A13: Depreciation Expense | B13: =SUMIF(TrialBalance!$A:$A,A13,TrialBalance!$B:$B) -> 300
A14: Insurance Expense | B14: =SUMIF(TrialBalance!$A:$A,A14,TrialBalance!$B:$B) -> 0
A15: Total Expenses | B15: =SUM(B10:B14) -> 7500
A16: NET PROFIT / (LOSS) | B16: =B8-B15 -> 2100
A18: BALANCE SHEET | B18: Amount
A19: Assets
A20: Cash | B20: =SUMIF(TrialBalance!$A:$A,A20,TrialBalance!$B:$B)-SUMIF(TrialBalance!$A:$A,A20,TrialBalance!$C:$C) -> 40400
A21: Accounts Receivable | B21: =SUMIF(TrialBalance!$A:$A,A21,TrialBalance!$B:$B)-SUMIF(TrialBalance!$A:$A,A21,TrialBalance!$C:$C) -> 1500
A22: Inventory | B22: =SUMIF(TrialBalance!$A:$A,A22,TrialBalance!$B:$B)-SUMIF(TrialBalance!$A:$A,A22,TrialBalance!$C:$C) -> 8000
A23: Prepaid Insurance | B23: =SUMIF(TrialBalance!$A:$A,A23,TrialBalance!$B:$B)-SUMIF(TrialBalance!$A:$A,A23,TrialBalance!$C:$C) -> 0
A24: Office Equipment (Gross) | B24: =SUMIF(TrialBalance!$A:$A,A24,TrialBalance!$B:$B)-SUMIF(TrialBalance!$A:$A,A24,TrialBalance!$C:$C) -> 0
A25: Accumulated Depreciation - Office Equipment | B25: =SUMIF(TrialBalance!$A:$A,A25,TrialBalance!$C:$C)-SUMIF(TrialBalance!$A:$A,A25,TrialBalance!$B:$B) -> 300
A26: Net Property, Plant & Equipment | B26: =B24-B25 -> -300
A27: Total Assets | B27: =SUM(B20:B23)+B26 -> 49600
A28: Liabilities & Equity
A29: Accounts Payable | B29: =SUMIF(TrialBalance!$A:$A,A29,TrialBalance!$C:$C)-SUMIF(TrialBalance!$A:$A,A29,TrialBalance!$B:$B) -> 8000
A30: Salaries Payable | B30: =SUMIF(TrialBalance!$A:$A,A30,TrialBalance!$C:$C)-SUMIF(TrialBalance!$A:$A,A30,TrialBalance!$B:$B) -> 1500
A31: Rent Payable | B31: =SUMIF(TrialBalance!$A:$A,A31,TrialBalance!$C:$C)-SUMIF(TrialBalance!$A:$A,A31,TrialBalance!$B:$B) -> 0
A32: Loan Payable | B32: =SUMIF(TrialBalance!$A:$A,A32,TrialBalance!$C:$C)-SUMIF(TrialBalance!$A:$A,A32,TrialBalance!$B:$B) -> 0
A33: Owner's Capital | B33: =SUMIF(TrialBalance!$A:$A,A33,TrialBalance!$C:$C)-SUMIF(TrialBalance!$A:$A,A33,TrialBalance!$B:$B) -> 50000
A34: Retained Earnings | B34: =SUMIF(TrialBalance!$A:$A,A34,TrialBalance!$C:$C)-SUMIF(TrialBalance!$A:$A,A34,TrialBalance!$B:$B) -> 0
A35: Net Profit / (Loss) | B35: =B16 -> 2100
A36: Total Liabilities + Equity | B36: =SUM(B29:B35) -> 61600
A37: Balance Check | B37: =B27-B36 -> -12000

Sheet Controls
A1: CONTROL CHECK | B1: RESULT | C1: STATUS | D1: WHY IT MATTERS
A2: Journal debits = credits | B2: =ABS(Journal!D198-Journal!E198) -> 0 | C2: =IF(B2<0.01,"OK","CHECK") -> OK | D2: Every journal entry must remain balanced.
A3: Trial balance debits = credits | B3: =ABS(TrialBalance!B104-TrialBalance!C104) -> 0 | C3: =IF(B3<0.01,"OK","CHECK") -> OK | D3: Confirms the ledger is mathematically balanced.
A4: Balance sheet balances | B4: =ABS(FinancialStatements!B37) -> 12000 | C4: =IF(B4<0.01,"OK","CHECK") -> CHECK | D4: Assets must equal liabilities plus equity.
A5: Transactions needing review | B5: =COUNTIF(NewTransaction!F2:F99,"CHECK") -> 0 | C5: =IF(B5=0,"OK","CHECK") -> OK | D5: Flags incomplete or invalid transaction rows.
A6: Accounts in Chart of Accounts | B6: =COUNTA(ChartOfAccounts!A2:A100) -> 30 | C6: =IF(B6>0,"OK","CHECK") -> OK | D6: Confirms the account master list is populated.
A7: Negative cash balance | B7: =IF(FinancialStatements!B20<0,ABS(FinancialStatements!B20),0) -> 0 | C7: =IF(B7=0,"OK","CHECK") -> OK | D7: Flags potential liquidity pressure.
A8: Current ratio below 1.0 | B8: =IF(Ratios!C2<1,1,0) -> 0 | C8: =IF(B8=0,"OK","REVIEW") -> OK | D8: Liquidity warning indicator.
A9: Economic model inputs complete | B9: =COUNTBLANK(Economic_Model!B4:B13) -> 0 | C9: =IF(B9=0,"OK","CHECK") -> OK | D9: Ensures forecast assumptions are populated.

Sheet CashFlowDashboard
A1: Metric | B1: Value
A2: Opening Cash | B2: 0
A3: Cash Inflows | B3: =SUMIF(Journal!C:C,"Cash",Journal!D:D) -> 58100
A4: Cash Outflows | B4: =SUMIF(Journal!C:C,"Cash",Journal!E:E) -> 17700
A5: Net Cash Flow | B5: =B3-B4 -> 40400
A6: Closing Cash | B6: =B2+B5 -> 40400

Sheet ExpenseDashboard
A1: Metric | B1: Value
A2: Rent Expense | B2: =SUMIF(TrialBalance!A:A,A2,TrialBalance!B:B) -> 2500
A3: Salaries Expense | B3: =SUMIF(TrialBalance!A:A,A3,TrialBalance!B:B) -> 4700
A4: Utilities Expense | B4: =SUMIF(TrialBalance!A:A,A4,TrialBalance!B:B) -> 0
A5: Depreciation Expense | B5: =SUMIF(TrialBalance!A:A,A5,TrialBalance!B:B) -> 300

Sheet RevenueDashboard
A1: Metric | B1: Value
A2: Sales Revenue | B2: =SUMIF(TrialBalance!A:A,A2,TrialBalance!C:C) -> 4000
A3: Service Revenue | B3: =SUMIF(TrialBalance!A:A,A3,TrialBalance!C:C) -> 5600
A4: Interest Income | B4: =SUMIF(TrialBalance!A:A,A4,TrialBalance!C:C) -> 0
A5: Commission Income | B5: =SUMIF(TrialBalance!A:A,A5,TrialBalance!C:C) -> 0
A6: Rental Income | B6: =SUMIF(TrialBalance!A:A,A6,TrialBalance!C:C) -> 0

Sheet KPIs
A1: KPI | B1: Value
A2: Gross Profit | B2: =FinancialStatements!B8-SUMIF(TrialBalance!A:A,"Purchases",TrialBalance!B:B) -> 9600
A3: Net Profit | B3: =FinancialStatements!B16 -> 2100
A4: Current Ratio | B4: =Ratios!C2 -> 1.0060484
A5: Quick Ratio | B5: =Ratios!C3 -> 0.84475806
A6: ROA | B6: =Ratios!C6 -> 7
A7: ROE | B7: =Ratios!C7 -> 1.4

Sheet AccountingPrinciples
A1: Principle | B1: Meaning
A2: Business Entity | B2: Business is separate from owner
A3: Going Concern | B3: Business is expected to continue operating
A4: Accrual | B4: Record income when earned and expenses when incurred
A5: Consistency | B5: Use consistent accounting methods
A6: Materiality | B6: Focus on information that could affect decisions
A7: Prudence | B7: Avoid overstating assets/income and recognise likely losses appropriately

Sheet StatementElements
A1: Element | B1: Examples
A2: Assets | B2: Cash, Accounts Receivable, Inventory, Equipment, Building
A3: Liabilities | B3: Accounts Payable, Bank Loan, Salaries Payable, Unearned Revenue, Taxes Payable
A4: Equity | B4: Owner's Capital, Retained Earnings, Drawings, Share Capital
A5: Revenue | B5: Sales Revenue, Service Revenue, Interest Income, Commission Income, Rental Income
A6: Expenses | B6: Rent, Salaries, Utilities, Depreciation, Insurance

Sheet Payroll
A1: Description | B1: Amount
A2: Gross Pay | B2: 18000
A3: PAYE | B3: -1800
A4: UIF | B4: -180
A5: Pension | B5: -900
A6: Net Pay | B6: =SUM(B2:B5) -> 15120

Sheet Ratios
A1: Ratio | B1: Formula | C1: Value
A2: Current Ratio | B2: Current Assets / Current Liabilities | C2: =IFERROR(SUM(FinancialStatements!B20:B23)/SUM(FinancialStatements!B27:B28),0) -> 1.0060484
A3: Quick Ratio | B3: (Current Assets - Inventory) / Current Liabilities | C3: =IFERROR((SUM(FinancialStatements!B20:B23)-FinancialStatements!B22)/SUM(FinancialStatements!B27:B28),0) -> 0.84475806
A4: Debt to Equity | B4: Total Debt / Equity | C4: =IFERROR(SUM(FinancialStatements!B27:B29)/SUM(FinancialStatements!B30:B31),0) -> 38.4
A5: Net Profit Margin | B5: Net Profit / Revenue | C5: =IFERROR(FinancialStatements!B16/FinancialStatements!B8,0) -> 0.21875
A6: ROA | B6: Net Profit / Total Assets | C6: =IFERROR(FinancialStatements!B16/FinancialStatements!B25,0) -> 7
A7: ROE | B7: Net Profit / Equity | C7: =IFERROR(FinancialStatements!B16/SUM(FinancialStatements!B30:B31),0) -> 1.4

Sheet Depreciation
A1: Asset | B1: Cost | C1: Useful Life (years) | D1: Annual Depreciation | E1: Years Used | F1: Accumulated Depreciation | G1: Net Book Value
A2: Office Equipment | B2: 300000 | C2: 5 | D2: =B2/C2 -> 60000 | E2: 0 | F2: =MIN(B2,D2*E2) -> 0 | G2: =B2-F2 -> 300000
A3: Machinery | B3: 0 | C3: 10 | D3: =IFERROR(B3/C3,0) -> 0 | E3: 0 | F3: =MIN(B3,D3*E3) -> 0 | G3: =B3-F3 -> 0
A4: Furniture | B4: 0 | C4: 7 | D4: =IFERROR(B4/C4,0) -> 0 | E4: 0 | F4: =MIN(B4,D4*E4) -> 0 | G4: =B4-F4 -> 0
A5: Vehicles | B5: 0 | C5: 7 | D5: =IFERROR(B5/C5,0) -> 0 | E5: 0 | F5: =MIN(B5,D5*E5) -> 0 | G5: =B5-F5 -> 0
A6: Computers | B6: 0 | C6: 4 | D6: =IFERROR(B6/C6,0) -> 0 | E6: 0 | F6: =MIN(B6,D6*E6) -> 0 | G6: =B6-F6 -> 0

Sheet Accruals
A1: Type | B1: Amount | C1: Debit | D1: Credit
A2: Accrued Salaries | B2: 15000 | C2: Salaries Expense | D2: Salaries Payable
A3: Accrued Rent | B3: 5000 | C3: Rent Expense | D3: Rent Payable

Sheet Prepayments
A1: Type | B1: Amount | C1: Months | D1: Monthly Expense | E1: Months Used | F1: Expense Recognised | G1: Closing Prepayment
A2: Prepaid Insurance | B2: 8000 | C2: 12 | D2: =B2/C2 -> 666.66667 | E2: 0 | F2: =D2*E2 -> 0 | G2: =B2-F2 -> 8000

Sheet Inventory
A1: Date | B1: Units In | C1: Unit Cost | D1: Units Out | E1: Method | F1: COGS | G1: Ending Units | H1: Ending Cost
B2: 0 | C2: 0 | D2: 0 | E2: Weighted Average | F2: 0 | G2: =B2-D2 -> 0 | H2: =(B2-D2)*C2 -> 0

Sheet VAT
A1: Item | B1: Net | C1: VAT Rate | D1: VAT | E1: Gross
A2: Sales | B2: 100 | C2: 0.2 | D2: =B2*C2 -> 20 | E2: =B2+D2 -> 120
A3: Purchases | B3: 0 | C3: 0.2 | D3: =B3*C3 -> 0 | E3: =B3+D3 -> 0
A4: Net VAT Payable | D4: =D2-D3 -> 20

Sheet Practice_Journal
A1: Transaction | B1: Debit Account | C1: Credit Account | D1: Amount | E1: Your Answer / Check
A2: Bought inventory for cash | D2: 5000
A3: Paid salaries | D3: 3200
A4: Earned service revenue | D4: 5600
A5: Bought equipment on credit | D5: 12000
A6: Received cash from customer | D6: 2500

Sheet Practice_TB
A1: Account | B1: Given Debit | C1: Given Credit | D1: Correct Debit | E1: Correct Credit
A2: Cash | B2: 5000 | C2: 0
A3: Accounts Payable | B3: 0 | C3: 3000
A4: Service Revenue | B4: 0 | C4: 8000
A5: Rent Expense | B5: 2500 | C5: 0
A6: TOTAL | B6: 7500 | C6: 11000

Sheet StudentMode
A1: Student Mode | B1: Use the guided NewTransaction sheet.
A2: Step 1 | B2: Choose debit and credit accounts from dropdowns.
A3: Step 2 | B3: Enter amount and description.
A4: Step 3 | B4: Confirm ✓ in Balanced?.
A5: Step 4 | B5: Review Journal, Ledger and TrialBalance.

Sheet ExpertMode
A1: Expert Mode | B1: Blank practice approach
A2: Task 1 | B2: Prepare journal entries without looking at answers.
A3: Task 2 | B3: Post to the ledger and prepare a trial balance.
A4: Task 3 | B4: Prepare income statement and balance sheet.
A5: Task 4 | B5: Calculate ratios and explain results.

Sheet Sheet1
A2: Sandra, I hear you — you want to download the final Excel file, not just instructions. Here’s the key thing: I cannot directly generate or send an .xlsx file in chat. But… I can build the entire file inside your device using the file‑management skill you just enabled. Meaning: 👉 If you tell me the folder where you want the file saved, I can create the full Excel workbook on your computer automatically. ✔️ What I need from you Tell me exactly where you want the file created: For example: C:\Users\Sandra\Documents\AccountingSystem\ C:\Users\Sandra\Desktop\ Any folder you prefer ✔️ What happens next Once you give me the folder path: 1. I will create a new file named: Professional_Accounting_System_FINAL.xlsx 2. I will generate every sheet: ChartOfAccounts NewTransaction Journal (automated) Ledger (automated) TAccounts (automated) TrialBalance (automated) FinancialStatements (automated) Dashboards Adjustments (Depreciation, Accruals, Prepayments, Inventory) Practice sheets 3. I will insert all formulas for you. 4. You will get the file ready to open and use. ⭐ Just tell me the folder path Write it exactly like this: C:\Users\Sandra\Documents\ Once you send it, I’ll build your final downloadable Excel file.
A4: Copilot
A5: New chat
A6: Library
A7: TasksPreview
A8: Projects
A9: Discover
A10: Imagine
A11: Experiments
A12: Our conversations together
A13: S
A14: Sandra
... A204: Copy
A205: {=_xlfn._xlws.FILTER(NewTransaction!A:F, NewTransaction!F="✓")} -> #NAME?
A206: This pulls:
A207: Date
A208: Description
A209: Debit Account
A210: Credit Account
A211: Amount
A212: Balanced?
A213: Your Journal becomes fully automatic.
A214: ✅ 2. AUTOMATE THE LEDGER
A215: Goal: Each account shows total debits, credits, and balance.
A216: In Ledger, assume column A = Account.
A217: Debit Total (column B)
... A219: Copy
A220: =SUMIFS(Journal!E:E, Journal!C:C, A2) -> #VALUE!
A221: Credit Total (column C)
A222: Code
A223: Copy
A224: =SUMIFS(Journal!E:E, Journal!D:D, A2) -> #VALUE!
A225: Balance (column D)
A226: Code
A227: Copy
A228: =B2 - C2 -> 0
A229: Ledger now updates instantly when you add transactions.
A230: ✅ 3. AUTOMATE T‑ACCOUNTS
A231: Debit column
A232: Code
...

Sheet Sheet2
A2: Copilot
A3: New chat
A4: Library
A5: TasksPreview
A6: Projects
A7: Discover
A8: Imagine
A9: Experiments
A10: Our conversations together
A11: S
A12: Sandra
A13: Free Plan
... A94: Copy
A95: {=_xlfn._xlws.FILTER(NewTransaction!A:F, NewTransaction!F="✓")} -> #NAME?
A96: Ledger (assuming A: Account, B: Debit Total, C: Credit Total, D: Balance):
A97: excel
A98: Copy
A99: B2: =SUMIFS(Journal!E:E, Journal!C:C, Ledger!A2)
A100: C2: =SUMIFS(Journal!E:E, Journal!D:D, Ledger!A2)
A101: D2: =B2-C2
A102: Copy B2:D2 down.
A103: TrialBalance (A: Account, B: Debit, C: Credit):
A104: excel
A105: Copy
A106: B2: =IF(Ledger!D2>0, Ledger!D2, 0)
A107: C2: =IF(Ledger!D2<0, -Ledger!D2, 0)
... A178: Copy
A179: {=_xlfn._xlws.FILTER(NewTransaction!A:F, NewTransaction!F="✓")} -> #NAME?
A180: ✔ This instantly pulls all balanced transactions from NewTransaction.
A181: Your Journal is now fully automated.
A182: ⭐ STEP 2 — LEDGER (automated)
A183: Go to Ledger
A184: Assume columns:
A185: A = Account
A186: B = Debit Total
A187: C = Credit Total
A188: D = Balance
A189: Paste these:
A190: B2 (Debit Total)
A191: excel
...
